<?xml version="1.0" ?>
<robot name="auto_clean" xmlns:xacro="http://www.ros.org/wiki/xacro">

<xacro:include filename="$(find auto_clean_description)/urdf/materials.xacro" />
<xacro:include filename="$(find auto_clean_description)/urdf/auto_clean.trans" />
<xacro:include filename="$(find auto_clean_description)/urdf/auto_clean.gazebo" />
<link name="base_link">
  <inertial>
    <origin xyz="-0.0009276695570702301 0.01774999674309802 0.037492237888275465" rpy="0 0 0"/>
    <mass value="0.49621205453581585"/>
    <inertia ixx="0.000708" iyy="0.000415" izz="0.000913" ixy="-0.0" iyz="-0.0" ixz="-4.1e-05"/>
  </inertial>
  <visual>
    <origin xyz="0 0 0" rpy="0 0 0"/>
    <geometry>
      <mesh filename="package://auto_clean_description/meshes/base_link.stl" scale="0.001 0.001 0.001"/>
    </geometry>
    <material name="steel_satin"/>
  </visual>
  <collision>
    <origin xyz="0 0 0" rpy="0 0 0"/>
    <geometry>
      <mesh filename="package://auto_clean_description/meshes/base_link.stl" scale="0.001 0.001 0.001"/>
    </geometry>
  </collision>
</link>

<link name="right_wheel_v1_1">
  <inertial>
    <origin xyz="-2.112893193739751e-15 -0.006249999999999922 2.7755575615628914e-17" rpy="0 0 0"/>
    <mass value="0.0714589021180024"/>
    <inertia ixx="1.9e-05" iyy="2.9e-05" izz="1.9e-05" ixy="0.0" iyz="0.0" ixz="0.0"/>
  </inertial>
  <visual>
    <origin xyz="-0.01725 0.03625 -0.032" rpy="0 0 0"/>
    <geometry>
      <mesh filename="package://auto_clean_description/meshes/right_wheel_v1_1.stl" scale="0.001 0.001 0.001"/>
    </geometry>
    <material name="rubber_hard"/>
  </visual>
  <collision>
    <origin xyz="-0.01725 0.03625 -0.032" rpy="0 0 0"/>
    <geometry>
      <mesh filename="package://auto_clean_description/meshes/right_wheel_v1_1.stl" scale="0.001 0.001 0.001"/>
    </geometry>
  </collision>
</link>

<link name="left_wheel_v1_1">
  <inertial>
    <origin xyz="-2.0643209364124004e-15 0.006249999999999992 6.938893903907228e-18" rpy="0 0 0"/>
    <mass value="0.0714589021180024"/>
    <inertia ixx="1.9e-05" iyy="2.9e-05" izz="1.9e-05" ixy="0.0" iyz="-0.0" ixz="0.0"/>
  </inertial>
  <visual>
    <origin xyz="-0.01725 -0.07175 -0.032" rpy="0 0 0"/>
    <geometry>
      <mesh filename="package://auto_clean_description/meshes/left_wheel_v1_1.stl" scale="0.001 0.001 0.001"/>
    </geometry>
    <material name="rubber_hard"/>
  </visual>
  <collision>
    <origin xyz="-0.01725 -0.07175 -0.032" rpy="0 0 0"/>
    <geometry>
      <mesh filename="package://auto_clean_description/meshes/left_wheel_v1_1.stl" scale="0.001 0.001 0.001"/>
    </geometry>
  </collision>
</link>

<link name="front_Castor_1">
  <inertial>
    <origin xyz="0.050000000000089556 4.764556804648379e-13 -0.0243934019095119" rpy="0 0 0"/>
    <mass value="0.03957987776285164"/>
    <inertia ixx="6e-06" iyy="6e-06" izz="2e-06" ixy="0.0" iyz="-0.0" ixz="-0.0"/>
  </inertial>
  <visual>
    <origin xyz="-0.015 -0.01775 -0.043" rpy="0 0 0"/>
    <geometry>
      <mesh filename="package://auto_clean_description/meshes/front_Castor_1.stl" scale="0.001 0.001 0.001"/>
    </geometry>
    <material name="steel_satin"/>
  </visual>
  <collision>
    <origin xyz="-0.015 -0.01775 -0.043" rpy="0 0 0"/>
    <geometry>
      <mesh filename="package://auto_clean_description/meshes/front_Castor_1.stl" scale="0.001 0.001 0.001"/>
    </geometry>
  </collision>
</link>

<link name="rear_Castor_1">
  <inertial>
    <origin xyz="-0.04999999999991038 4.765007832752133e-13 -0.02439340190951189" rpy="0 0 0"/>
    <mass value="0.03957987776285164"/>
    <inertia ixx="6e-06" iyy="6e-06" izz="2e-06" ixy="0.0" iyz="-0.0" ixz="-0.0"/>
  </inertial>
  <visual>
    <origin xyz="-0.015 -0.01775 -0.043" rpy="0 0 0"/>
    <geometry>
      <mesh filename="package://auto_clean_description/meshes/rear_Castor_1.stl" scale="0.001 0.001 0.001"/>
    </geometry>
    <material name="steel_satin"/>
  </visual>
  <collision>
    <origin xyz="-0.015 -0.01775 -0.043" rpy="0 0 0"/>
    <geometry>
      <mesh filename="package://auto_clean_description/meshes/rear_Castor_1.stl" scale="0.001 0.001 0.001"/>
    </geometry>
  </collision>
</link>

<link name="ydlidar_x4_v1_1">
  <inertial>
    <origin xyz="-0.008294099570319475 -1.0408340855860843e-17 0.035201142222790985" rpy="0 0 0"/>
    <mass value="1.1515616542314233"/>
    <inertia ixx="0.000489" iyy="0.000861" izz="0.000987" ixy="-0.0" iyz="0.0" ixz="-0.000148"/>
  </inertial>
  <visual>
    <origin xyz="-0.015 -0.01775 -0.129" rpy="0 0 0"/>
    <geometry>
      <mesh filename="package://auto_clean_description/meshes/ydlidar_x4_v1_1.stl" scale="0.001 0.001 0.001"/>
    </geometry>
    <material name="steel_satin"/>
  </visual>
  <collision>
    <origin xyz="-0.015 -0.01775 -0.079" rpy="0 0 0"/>
    <geometry>
      <mesh filename="package://auto_clean_description/meshes/ydlidar_x4_v1_1.stl" scale="0.001 0.001 0.001"/>
    </geometry>
  </collision>
</link>

<link name="right_connect_1">
  <inertial>
    <origin xyz="0.06530375868067693 -0.030000000000000023 0.0016078607775464535" rpy="0 0 0"/>
    <mass value="0.00762746048900369"/>
    <inertia ixx="1e-06" iyy="3e-06" izz="3e-06" ixy="0.0" iyz="-0.0" ixz="-0.0"/>
  </inertial>
  <visual>
    <origin xyz="-0.015 -0.01775 -0.043" rpy="0 0 0"/>
    <geometry>
      <mesh filename="package://auto_clean_description/meshes/right_connect_1.stl" scale="0.001 0.001 0.001"/>
    </geometry>
    <material name="paint_enamel_glossy_blue"/>
  </visual>
  <collision>
    <origin xyz="-0.015 -0.01775 -0.043" rpy="0 0 0"/>
    <geometry>
      <mesh filename="package://auto_clean_description/meshes/right_connect_1.stl" scale="0.001 0.001 0.001"/>
    </geometry>
  </collision>
</link>

<link name="left_connect_v2_1">
  <inertial>
    <origin xyz="0.06530375868067693 0.02999999999999996 0.0016078607775464535" rpy="0 0 0"/>
    <mass value="0.00762746048900369"/>
    <inertia ixx="1e-06" iyy="3e-06" izz="3e-06" ixy="0.0" iyz="0.0" ixz="-0.0"/>
  </inertial>
  <visual>
    <origin xyz="-0.015 -0.01775 -0.043" rpy="0 0 0"/>
    <geometry>
      <mesh filename="package://auto_clean_description/meshes/left_connect_v2_1.stl" scale="0.001 0.001 0.001"/>
    </geometry>
    <material name="paint_enamel_glossy_blue"/>
  </visual>
  <collision>
    <origin xyz="-0.015 -0.01775 -0.043" rpy="0 0 0"/>
    <geometry>
      <mesh filename="package://auto_clean_description/meshes/left_connect_v2_1.stl" scale="0.001 0.001 0.001"/>
    </geometry>
  </collision>
</link>

<link name="right_brush_motor_1">
  <inertial>
    <origin xyz="-5.6292957953771317e-05 7.426492519901559e-05 -0.011748993662980753" rpy="0 0 0"/>
    <mass value="0.03635919927939921"/>
    <inertia ixx="4e-06" iyy="4e-06" izz="3e-06" ixy="0.0" iyz="-0.0" ixz="0.0"/>
  </inertial>
  <visual>
    <origin xyz="-0.095 0.01225 -0.053" rpy="0 0 0"/>
    <geometry>
      <mesh filename="package://auto_clean_description/meshes/right_brush_motor_1.stl" scale="0.001 0.001 0.001"/>
    </geometry>
    <material name="steel_satin"/>
  </visual>
  <collision>
    <origin xyz="-0.095 0.01225 -0.053" rpy="0 0 0"/>
    <geometry>
      <mesh filename="package://auto_clean_description/meshes/right_brush_motor_1.stl" scale="0.001 0.001 0.001"/>
    </geometry>
  </collision>
</link>

<link name="left_brush_motor_1">
  <inertial>
    <origin xyz="7.426492519904682e-05 5.6292957953715805e-05 -0.011641764747318109" rpy="0 0 0"/>
    <mass value="0.03635919927939921"/>
    <inertia ixx="4e-06" iyy="4e-06" izz="3e-06" ixy="-0.0" iyz="-0.0" ixz="-0.0"/>
  </inertial>
  <visual>
    <origin xyz="-0.095 -0.04775 -0.053" rpy="0 0 0"/>
    <geometry>
      <mesh filename="package://auto_clean_description/meshes/left_brush_motor_1.stl" scale="0.001 0.001 0.001"/>
    </geometry>
    <material name="steel_satin"/>
  </visual>
  <collision>
    <origin xyz="-0.095 -0.04775 -0.053" rpy="0 0 0"/>
    <geometry>
      <mesh filename="package://auto_clean_description/meshes/left_brush_motor_1.stl" scale="0.001 0.001 0.001"/>
    </geometry>
  </collision>
</link>

<link name="right_brush_1">
  <inertial>
    <origin xyz="-2.9837243786801082e-15 -2.949029909160572e-17 0.0015001581078550406" rpy="0 0 0"/>
    <mass value="0.0005746028265928243"/>
    <inertia ixx="0.0" iyy="0.0" izz="0.0" ixy="0.0" iyz="-0.0" ixz="0.0"/>
  </inertial>
  <visual>
    <origin xyz="-0.095 0.01225 -0.010733" rpy="0 0 0"/>
    <geometry>
      <mesh filename="package://auto_clean_description/meshes/right_brush_1.stl" scale="0.001 0.001 0.001"/>
    </geometry>
    <material name="paint_enamel_glossy_green"/>
  </visual>
  <collision>
    <origin xyz="-0.095 0.01225 -0.010733" rpy="0 0 0"/>
    <geometry>
      <mesh filename="package://auto_clean_description/meshes/right_brush_1.stl" scale="0.001 0.001 0.001"/>
    </geometry>
  </collision>
</link>

<link name="left_brush_1">
  <inertial>
    <origin xyz="-2.9698465908722937e-15 -4.163336342344337e-17 0.0015003870235176867" rpy="0 0 0"/>
    <mass value="0.0005746028265928243"/>
    <inertia ixx="0.0" iyy="0.0" izz="0.0" ixy="0.0" iyz="0.0" ixz="0.0"/>
  </inertial>
  <visual>
    <origin xyz="-0.095 -0.04775 -0.01084" rpy="0 0 0"/>
    <geometry>
      <mesh filename="package://auto_clean_description/meshes/left_brush_1.stl" scale="0.001 0.001 0.001"/>
    </geometry>
    <material name="paint_enamel_glossy_green"/>
  </visual>
  <collision>
    <origin xyz="-0.095 -0.04775 -0.01084" rpy="0 0 0"/>
    <geometry>
      <mesh filename="package://auto_clean_description/meshes/left_brush_1.stl" scale="0.001 0.001 0.001"/>
    </geometry>
  </collision>
</link>

<joint name="right_drive" type="continuous">
  <origin xyz="0.01725 -0.03625 0.032" rpy="0 0 0"/>
  <parent link="base_link"/>
  <child link="right_wheel_v1_1"/>
  <axis xyz="-0.0 1.0 0.0"/>
</joint>

<joint name="left_drive" type="continuous">
  <origin xyz="0.01725 0.07175 0.032" rpy="0 0 0"/>
  <parent link="base_link"/>
  <child link="left_wheel_v1_1"/>
  <axis xyz="0.0 1.0 0.0"/>
</joint>

<joint name="Rigid4" type="fixed">
  <origin xyz="0.015 0.01775 0.043" rpy="0 0 0"/>
  <parent link="base_link"/>
  <child link="front_Castor_1"/>
</joint>

<joint name="Rigid5" type="fixed">
  <origin xyz="0.015 0.01775 0.043" rpy="0 0 0"/>
  <parent link="base_link"/>
  <child link="rear_Castor_1"/>
</joint>

<joint name="Rigid6" type="fixed">
  <origin xyz="0.015 0.01775 0.129" rpy="0 0 0"/>
  <parent link="base_link"/>
  <child link="ydlidar_x4_v1_1"/>
</joint>

<joint name="Rigid7" type="fixed">
  <origin xyz="0.015 0.01775 0.043" rpy="0 0 0"/>
  <parent link="base_link"/>
  <child link="right_connect_1"/>
</joint>

<joint name="Rigid8" type="fixed">
  <origin xyz="0.015 0.01775 0.043" rpy="0 0 0"/>
  <parent link="base_link"/>
  <child link="left_connect_v2_1"/>
</joint>

<joint name="Rigid9" type="fixed">
  <origin xyz="0.08 -0.03 0.01" rpy="0 0 0"/>
  <parent link="right_connect_1"/>
  <child link="right_brush_motor_1"/>
</joint>

<joint name="Rigid10" type="fixed">
  <origin xyz="0.08 0.03 0.01" rpy="0 0 0"/>
  <parent link="left_connect_v2_1"/>
  <child link="left_brush_motor_1"/>
</joint>

<joint name="right_brush" type="continuous">
  <origin xyz="0.0 0.0 -0.042267" rpy="0 0 0"/>
  <parent link="right_brush_motor_1"/>
  <child link="right_brush_1"/>
  <axis xyz="0.0 0.0 -1.0"/>
</joint>

<joint name="left_brush" type="continuous">
  <origin xyz="0.0 0.0 -0.04216" rpy="0 0 0"/>
  <parent link="left_brush_motor_1"/>
  <child link="left_brush_1"/>
  <axis xyz="0.0 0.0 -1.0"/>
</joint>

</robot>
